2020-07-14 21:05:07,009 -  nornir.core -     INFO -        run() - Running task 'napalm_get' with args {'getters': ['facts', 'arp_table']} on 2 hosts
2020-07-14 21:05:47,713 -  nornir.core -     INFO -        run() - Running task 'napalm_get' with args {'getters': ['facts', 'arp_table']} on 2 hosts
2020-07-14 21:06:49,546 -  nornir.core -     INFO -        run() - Running task 'napalm_get' with args {'getters': ['facts', 'arp_table']} on 2 hosts
2020-07-14 21:07:22,117 -  nornir.core -     INFO -        run() - Running task 'napalm_get' with args {'getters': ['facts', 'arp_table']} on 2 hosts
2020-07-14 21:10:36,916 -  nornir.core -     INFO -        run() - Running task 'netmiko_send_command' with args {'command_string': 'sh arp'} on 2 hosts
2020-07-14 21:10:57,916 -  nornir.core -     INFO -        run() - Running task 'netmiko_send_command' with args {'command_string': 'sh arp'} on 2 hosts
2020-07-14 21:13:42,502 -  nornir.core -     INFO -        run() - Running task 'netmiko_send_command' with args {'command_string': 'sh ip int br'} on 2 hosts
2020-07-14 21:15:21,247 -  nornir.core -     INFO -        run() - Running task 'netmiko_send_command' with args {'command_string': 'sh arp'} on 2 hosts
2020-07-15 08:18:47,817 -  nornir.core -     INFO -        run() - Running task 'Creating Backup Archive' with args {'name': 'Creating Backup Archive'} on 2 hosts
2020-07-15 08:20:03,526 -  nornir.core -     INFO -        run() - Running task 'Creating Backup Archive' with args {'name': 'Creating Backup Archive'} on 2 hosts
2020-07-15 08:21:34,407 -  nornir.core -     INFO -        run() - Running task 'Creating Backup Archive' with args {'name': 'Creating Backup Archive'} on 2 hosts
2020-07-15 08:22:25,875 -  nornir.core -     INFO -        run() - Running task 'Creating Backup Archive' with args {'name': 'Creating Backup Archive'} on 2 hosts
2020-07-15 08:25:25,767 -  nornir.core -     INFO -        run() - Running task 'Creating Backup Archive' with args {'name': 'Creating Backup Archive'} on 2 hosts
2020-07-15 08:42:24,432 -  nornir.core -     INFO -        run() - Running task 'Creating Backup Archive' with args {'name': 'Creating Backup Archive'} on 2 hosts
2020-07-15 08:51:46,787 -  nornir.core -     INFO -        run() - Running task 'Creating Backup Archive' with args {'name': 'Creating Backup Archive'} on 2 hosts
2020-07-15 08:52:10,696 -  nornir.core -     INFO -        run() - Running task 'Creating Backup Archive' with args {'name': 'Creating Backup Archive'} on 2 hosts
2020-07-15 08:55:24,238 -  nornir.core -     INFO -        run() - Running task 'Creating Backup Archive' with args {'name': 'Creating Backup Archive'} on 2 hosts
2020-07-15 08:56:26,790 -  nornir.core -     INFO -        run() - Running task 'Creating Backup Archive' with args {'name': 'Creating Backup Archive'} on 2 hosts
2020-07-15 08:57:59,255 -  nornir.core -     INFO -        run() - Running task 'napalm_get' with args {'getters': ['facts', 'arp_table']} on 2 hosts
2020-07-15 08:59:02,338 -  nornir.core -     INFO -        run() - Running task 'napalm_get' with args {'getters': ['facts', 'arp_table']} on 2 hosts
2020-07-15 09:30:59,306 -  nornir.core -     INFO -        run() - Running task 'Creating Backup Archive' with args {'name': 'Creating Backup Archive'} on 2 hosts
2020-07-15 09:31:44,653 -  nornir.core -     INFO -        run() - Running task 'Creating Backup Archive' with args {'name': 'Creating Backup Archive'} on 2 hosts
2020-07-15 09:53:36,455 -  nornir.core -     INFO -        run() - Running task 'Creating Backup Archive' with args {'name': 'Creating Backup Archive'} on 2 hosts
2020-07-15 09:53:42,464 - nornir.core.task -    ERROR -      start() - Host 'CORE-1': task 'Creating Backup Archive' failed with traceback:
Traceback (most recent call last):
  File "/Users/stephenamaki/Dropbox/netdevops/venv_nornir/lib/python3.8/site-packages/nornir/core/task.py", line 85, in start
    r = self.task(self, **self.params)
  File "get_config_archive1.py", line 21, in backup_configurations
    + str(dt.datetime.today().strftime("%Y-%m-%d"))
NameError: name 'dt' is not defined

2020-07-15 09:53:42,732 - nornir.core.task -    ERROR -      start() - Host 'CORE-2': task 'Creating Backup Archive' failed with traceback:
Traceback (most recent call last):
  File "/Users/stephenamaki/Dropbox/netdevops/venv_nornir/lib/python3.8/site-packages/nornir/core/task.py", line 85, in start
    r = self.task(self, **self.params)
  File "get_config_archive1.py", line 21, in backup_configurations
    + str(dt.datetime.today().strftime("%Y-%m-%d"))
NameError: name 'dt' is not defined

2020-07-15 09:54:02,386 -  nornir.core -     INFO -        run() - Running task 'Creating Backup Archive' with args {'name': 'Creating Backup Archive'} on 2 hosts
2020-07-15 09:54:08,321 - nornir.core.task -    ERROR -      start() - Host 'CORE-1': task 'Creating Backup Archive' failed with traceback:
Traceback (most recent call last):
  File "/Users/stephenamaki/Dropbox/netdevops/venv_nornir/lib/python3.8/site-packages/nornir/core/task.py", line 85, in start
    r = self.task(self, **self.params)
  File "get_config_archive1.py", line 21, in backup_configurations
    + str(dt.datetime.today().strftime("%Y-%m-%d"))
NameError: name 'dt' is not defined

2020-07-15 09:54:08,643 - nornir.core.task -    ERROR -      start() - Host 'CORE-2': task 'Creating Backup Archive' failed with traceback:
Traceback (most recent call last):
  File "/Users/stephenamaki/Dropbox/netdevops/venv_nornir/lib/python3.8/site-packages/nornir/core/task.py", line 85, in start
    r = self.task(self, **self.params)
  File "get_config_archive1.py", line 21, in backup_configurations
    + str(dt.datetime.today().strftime("%Y-%m-%d"))
NameError: name 'dt' is not defined

2020-07-15 10:23:18,488 -  nornir.core -     INFO -        run() - Running task 'Creating Backup Archive' with args {'name': 'Creating Backup Archive'} on 14 hosts
2020-07-15 10:23:23,152 - nornir.core.task -    ERROR -      start() - Host 'vMX-2': task 'napalm_get' failed with traceback:
Traceback (most recent call last):
  File "/Users/stephenamaki/Dropbox/netdevops/venv_nornir/lib/python3.8/site-packages/nornir/core/task.py", line 85, in start
    r = self.task(self, **self.params)
  File "/Users/stephenamaki/Dropbox/netdevops/venv_nornir/lib/python3.8/site-packages/nornir/plugins/tasks/networking/napalm_get.py", line 49, in napalm_get
    device = task.host.get_connection("napalm", task.nornir.config)
  File "/Users/stephenamaki/Dropbox/netdevops/venv_nornir/lib/python3.8/site-packages/nornir/core/inventory.py", line 294, in get_connection
    self.open_connection(
  File "/Users/stephenamaki/Dropbox/netdevops/venv_nornir/lib/python3.8/site-packages/nornir/core/inventory.py", line 345, in open_connection
    self.connections[connection].open(
  File "/Users/stephenamaki/Dropbox/netdevops/venv_nornir/lib/python3.8/site-packages/nornir/plugins/connections/napalm.py", line 51, in open
    connection.open()
  File "/Users/stephenamaki/Dropbox/netdevops/venv_nornir/lib/python3.8/site-packages/napalm/ios/ios.py", line 168, in open
    self.device = self._netmiko_open(
  File "/Users/stephenamaki/Dropbox/netdevops/venv_nornir/lib/python3.8/site-packages/napalm/base/base.py", line 102, in _netmiko_open
    self._netmiko_device.enable()
  File "/Users/stephenamaki/Dropbox/netdevops/venv_nornir/lib/python3.8/site-packages/netmiko/cisco_base_connection.py", line 21, in enable
    return super(CiscoBaseConnection, self).enable(
  File "/Users/stephenamaki/Dropbox/netdevops/venv_nornir/lib/python3.8/site-packages/netmiko/base_connection.py", line 1470, in enable
    raise ValueError(msg)
ValueError: Failed to enter enable mode. Please ensure you pass the 'secret' argument to ConnectHandler.

2020-07-15 10:23:23,152 - nornir.core.task -    ERROR -      start() - Host 'vMX-1': task 'napalm_get' failed with traceback:
Traceback (most recent call last):
  File "/Users/stephenamaki/Dropbox/netdevops/venv_nornir/lib/python3.8/site-packages/nornir/core/task.py", line 85, in start
    r = self.task(self, **self.params)
  File "/Users/stephenamaki/Dropbox/netdevops/venv_nornir/lib/python3.8/site-packages/nornir/plugins/tasks/networking/napalm_get.py", line 49, in napalm_get
    device = task.host.get_connection("napalm", task.nornir.config)
  File "/Users/stephenamaki/Dropbox/netdevops/venv_nornir/lib/python3.8/site-packages/nornir/core/inventory.py", line 294, in get_connection
    self.open_connection(
  File "/Users/stephenamaki/Dropbox/netdevops/venv_nornir/lib/python3.8/site-packages/nornir/core/inventory.py", line 345, in open_connection
    self.connections[connection].open(
  File "/Users/stephenamaki/Dropbox/netdevops/venv_nornir/lib/python3.8/site-packages/nornir/plugins/connections/napalm.py", line 51, in open
    connection.open()
  File "/Users/stephenamaki/Dropbox/netdevops/venv_nornir/lib/python3.8/site-packages/napalm/ios/ios.py", line 168, in open
    self.device = self._netmiko_open(
  File "/Users/stephenamaki/Dropbox/netdevops/venv_nornir/lib/python3.8/site-packages/napalm/base/base.py", line 102, in _netmiko_open
    self._netmiko_device.enable()
  File "/Users/stephenamaki/Dropbox/netdevops/venv_nornir/lib/python3.8/site-packages/netmiko/cisco_base_connection.py", line 21, in enable
    return super(CiscoBaseConnection, self).enable(
  File "/Users/stephenamaki/Dropbox/netdevops/venv_nornir/lib/python3.8/site-packages/netmiko/base_connection.py", line 1470, in enable
    raise ValueError(msg)
ValueError: Failed to enter enable mode. Please ensure you pass the 'secret' argument to ConnectHandler.

2020-07-15 10:23:23,153 - nornir.core.task -    ERROR -      start() - Host 'vMX-2': task 'Creating Backup Archive' failed with traceback:
Traceback (most recent call last):
  File "/Users/stephenamaki/Dropbox/netdevops/venv_nornir/lib/python3.8/site-packages/nornir/core/task.py", line 85, in start
    r = self.task(self, **self.params)
  File "get_config_archive1.py", line 14, in backup_configurations
    r = task.run(task=networking.napalm_get, getters=["config"])
  File "/Users/stephenamaki/Dropbox/netdevops/venv_nornir/lib/python3.8/site-packages/nornir/core/task.py", line 147, in run
    raise NornirSubTaskError(task=task, result=r)
nornir.core.exceptions.NornirSubTaskError: Subtask: <function napalm_get at 0x7ff1082705e0> (failed)


2020-07-15 10:23:23,153 - nornir.core.task -    ERROR -      start() - Host 'vMX-1': task 'Creating Backup Archive' failed with traceback:
Traceback (most recent call last):
  File "/Users/stephenamaki/Dropbox/netdevops/venv_nornir/lib/python3.8/site-packages/nornir/core/task.py", line 85, in start
    r = self.task(self, **self.params)
  File "get_config_archive1.py", line 14, in backup_configurations
    r = task.run(task=networking.napalm_get, getters=["config"])
  File "/Users/stephenamaki/Dropbox/netdevops/venv_nornir/lib/python3.8/site-packages/nornir/core/task.py", line 147, in run
    raise NornirSubTaskError(task=task, result=r)
nornir.core.exceptions.NornirSubTaskError: Subtask: <function napalm_get at 0x7ff1082705e0> (failed)


2020-07-15 10:23:24,205 - nornir.core.task -    ERROR -      start() - Host 'vMX-vCP': task 'napalm_get' failed with traceback:
Traceback (most recent call last):
  File "/Users/stephenamaki/Dropbox/netdevops/venv_nornir/lib/python3.8/site-packages/nornir/core/task.py", line 85, in start
    r = self.task(self, **self.params)
  File "/Users/stephenamaki/Dropbox/netdevops/venv_nornir/lib/python3.8/site-packages/nornir/plugins/tasks/networking/napalm_get.py", line 49, in napalm_get
    device = task.host.get_connection("napalm", task.nornir.config)
  File "/Users/stephenamaki/Dropbox/netdevops/venv_nornir/lib/python3.8/site-packages/nornir/core/inventory.py", line 294, in get_connection
    self.open_connection(
  File "/Users/stephenamaki/Dropbox/netdevops/venv_nornir/lib/python3.8/site-packages/nornir/core/inventory.py", line 345, in open_connection
    self.connections[connection].open(
  File "/Users/stephenamaki/Dropbox/netdevops/venv_nornir/lib/python3.8/site-packages/nornir/plugins/connections/napalm.py", line 51, in open
    connection.open()
  File "/Users/stephenamaki/Dropbox/netdevops/venv_nornir/lib/python3.8/site-packages/napalm/ios/ios.py", line 168, in open
    self.device = self._netmiko_open(
  File "/Users/stephenamaki/Dropbox/netdevops/venv_nornir/lib/python3.8/site-packages/napalm/base/base.py", line 102, in _netmiko_open
    self._netmiko_device.enable()
  File "/Users/stephenamaki/Dropbox/netdevops/venv_nornir/lib/python3.8/site-packages/netmiko/cisco_base_connection.py", line 21, in enable
    return super(CiscoBaseConnection, self).enable(
  File "/Users/stephenamaki/Dropbox/netdevops/venv_nornir/lib/python3.8/site-packages/netmiko/base_connection.py", line 1470, in enable
    raise ValueError(msg)
ValueError: Failed to enter enable mode. Please ensure you pass the 'secret' argument to ConnectHandler.

2020-07-15 10:23:24,205 - nornir.core.task -    ERROR -      start() - Host 'vMX-vCP': task 'Creating Backup Archive' failed with traceback:
Traceback (most recent call last):
  File "/Users/stephenamaki/Dropbox/netdevops/venv_nornir/lib/python3.8/site-packages/nornir/core/task.py", line 85, in start
    r = self.task(self, **self.params)
  File "get_config_archive1.py", line 14, in backup_configurations
    r = task.run(task=networking.napalm_get, getters=["config"])
  File "/Users/stephenamaki/Dropbox/netdevops/venv_nornir/lib/python3.8/site-packages/nornir/core/task.py", line 147, in run
    raise NornirSubTaskError(task=task, result=r)
nornir.core.exceptions.NornirSubTaskError: Subtask: <function napalm_get at 0x7ff1082705e0> (failed)


2020-07-15 10:27:59,422 -  nornir.core -     INFO -        run() - Running task 'Creating Backup Archive' with args {'name': 'Creating Backup Archive'} on 2 hosts
2020-07-15 10:33:26,047 -  nornir.core -     INFO -        run() - Running task 'Creating Backup Archive' with args {'name': 'Creating Backup Archive'} on 2 hosts
2020-07-15 10:36:56,924 -  nornir.core -     INFO -        run() - Running task 'Creating Backup Archive' with args {'name': 'Creating Backup Archive'} on 2 hosts
2020-07-15 10:38:17,081 -  nornir.core -     INFO -        run() - Running task 'Creating Backup Archive' with args {'name': 'Creating Backup Archive'} on 2 hosts
2020-07-15 10:39:41,591 -  nornir.core -     INFO -        run() - Running task 'Creating Backup Archive' with args {'name': 'Creating Backup Archive'} on 2 hosts
2020-07-15 10:42:07,661 -  nornir.core -     INFO -        run() - Running task 'Creating Backup Archive' with args {'name': 'Creating Backup Archive'} on 2 hosts
2020-07-15 10:49:40,439 -  nornir.core -     INFO -        run() - Running task 'Creating Backup Archive' with args {'name': 'Creating Backup Archive'} on 2 hosts
